Workbook

Sheet Data 2024
A1: South Shore Schools — FY24 spending vs Spring 2024 MCAS
A2: Same-year pairing: FY24 = school year 2023-24. Source: DESE RADAR district-comparison.xlsx
A4: District | B4: Type | C4: In-Dist FTE | D4: In-Dist PPE | E4: Total PPE | F4: ELA 3-8 %M+E | G4: Math 3-8 %M+E | H4: Avg M+E | I4: Low Inc % | J4: EL % | K4: SWD % | L4: ELA 10 %M+E | M4: Math 10 %M+E
A5: Abington | B5: K-12 | C5: 2142.5 | D5: 17097 | E5: 18473 | F5: 0.417 | G5: 0.416 | H5: =IFERROR(AVERAGE(F5,G5),"") -> 0.4165 | I5: 0.325 | J5: 0.117 | K5: 0.188 | L5: 0.453 | M5: 0.375
A6: Braintree | B6: K-12 | C6: 5313.5 | D6: 19549 | E6: 20829 | F6: 0.485 | G6: 0.557 | H6: =IFERROR(AVERAGE(F6,G6),"") -> 0.521 | I6: 0.276 | J6: 0.075 | K6: 0.224 | L6: 0.684 | M6: 0.684
A7: Bridgewater-Raynham | B7: K-12 Reg | C7: 5630.9 | D7: 16125 | E7: 16784 | F7: 0.371 | G7: 0.431 | H7: =IFERROR(AVERAGE(F7,G7),"") -> 0.401 | I7: 0.264 | J7: 0.034 | K7: 0.199 | L7: 0.525 | M7: 0.53
A8: Carver | B8: K-12 | C8: 1504.5 | D8: 19247 | E8: 20750 | F8: 0.286 | G8: 0.332 | H8: =IFERROR(AVERAGE(F8,G8),"") -> 0.309 | I8: 0.295 | J8: 0.019 | K8: 0.197 | L8: 0.543 | M8: 0.358
A9: Cohasset | B9: K-12 | C9: 1429.4 | D9: 22516 | E9: 24119 | F9: 0.679 | G9: 0.677 | H9: =IFERROR(AVERAGE(F9,G9),"") -> 0.678 | I9: 0.063 | J9: 0.003 | K9: 0.17 | L9: 0.927 | M9: 0.718
A10: Duxbury | B10: K-12 | C10: 2739.8 | D10: 20115 | E10: 21034 | F10: 0.637 | G10: 0.583 | H10: =IFERROR(AVERAGE(F10,G10),"") -> 0.61 | I10: 0.087 | J10: 0.006 | K10: 0.168 | L10: 0.782 | M10: 0.762
A11: East Bridgewater | B11: K-12 | C11: 2010.8 | D11: 17593 | E11: 18317 | F11: 0.407 | G11: 0.378 | H11: =IFERROR(AVERAGE(F11,G11),"") -> 0.3925 | I11: 0.279 | J11: 0.031 | K11: 0.193 | L11: 0.431 | M11: 0.272
A12: Halifax | B12: K-6 | C12: 548.8 | D12: 17023 | E12: 20264 | F12: 0.548 | G12: 0.551 | H12: =IFERROR(AVERAGE(F12,G12),"") -> 0.5495 | I12: 0.271 | J12: 0.011 | K12: 0.225 | L12: 0 | M12: 0.5
A13: Hanover | B13: K-12 | C13: 2605.4 | D13: 16823 | E13: 18075 | F13: 0.553 | G13: 0.594 | H13: =IFERROR(AVERAGE(F13,G13),"") -> 0.5735 | I13: 0.111 | J13: 0.017 | K13: 0.224 | L13: 0.8 | M13: 0.673
A14: Hingham | B14: K-12 | C14: 3679.1 | D14: 20479 | E14: 21837 | F14: 0.747 | G14: 0.722 | H14: =IFERROR(AVERAGE(F14,G14),"") -> 0.7345 | I14: 0.078 | J14: 0.007 | K14: 0.183 | L14: 0.857 | M14: 0.749
A15: Holbrook | B15: K-12 | C15: 1322.4 | D15: 17567 | E15: 18892 | F15: 0.334 | G15: 0.388 | H15: =IFERROR(AVERAGE(F15,G15),"") -> 0.361 | I15: 0.438 | J15: 0.088 | K15: 0.22 | L15: 0.409 | M15: 0.257
A16: Hull | B16: K-12 | C16: 752.3 | D16: 31139 | E16: 31821 | F16: 0.538 | G16: 0.461 | H16: =IFERROR(AVERAGE(F16,G16),"") -> 0.4995 | I16: 0.334 | J16: 0.016 | K16: 0.218 | L16: 0.578 | M16: 0.508
... A31: MASSACHUSETTS | B31: STATE | C31: 867936.7 | D31: 22408 | E31: 23159 | F31: 0.39 | G31: 0.41 | H31: =IFERROR(AVERAGE(F31,G31),"") -> 0.4 | I31: 0.422 | J31: 0.131 | K31: 0.202 | L31: 0.57 | M31: 0.48

Sheet Data 2023
A1: South Shore Schools — FY23 spending vs Spring 2023 MCAS
A2: Same-year pairing: FY23 = school year 2022-23. Source: DESE RADAR district-comparison.xlsx
A4: District | B4: Type | C4: In-Dist FTE | D4: In-Dist PPE | E4: Total PPE | F4: ELA 3-8 %M+E | G4: Math 3-8 %M+E | H4: Avg M+E | I4: Low Inc % | J4: EL % | K4: SWD % | L4: ELA 10 %M+E | M4: Math 10 %M+E
A5: Abington | B5: K-12 | C5: 2143.5 | D5: 16610 | E5: 17890 | F5: 0.479 | G5: 0.43 | H5: =IFERROR(AVERAGE(F5,G5),"") -> 0.4545 | I5: 0.344 | J5: 0.11 | K5: 0.178 | L5: 0.516 | M5: 0.368
A6: Braintree | B6: K-12 | C6: 5376.6 | D6: 17739 | E6: 19048 | F6: 0.521 | G6: 0.556 | H6: =IFERROR(AVERAGE(F6,G6),"") -> 0.5385 | I6: 0.27 | J6: 0.076 | K6: 0.216 | L6: 0.707 | M6: 0.717
A7: Bridgewater-Raynham | B7: K-12 Reg | C7: 5508.8 | D7: 15642 | E7: 16122 | F7: 0.396 | G7: 0.438 | H7: =IFERROR(AVERAGE(F7,G7),"") -> 0.417 | I7: 0.264 | J7: 0.028 | K7: 0.191 | L7: 0.549 | M7: 0.542
A8: Carver | B8: K-12 | C8: 1545 | D8: 18506 | E8: 19248 | F8: 0.291 | G8: 0.31 | H8: =IFERROR(AVERAGE(F8,G8),"") -> 0.3005 | I8: 0.31 | J8: 0.022 | K8: 0.189 | L8: 0.52 | M8: 0.408
A9: Cohasset | B9: K-12 | C9: 1405.9 | D9: 21828 | E9: 23212 | F9: 0.704 | G9: 0.702 | H9: =IFERROR(AVERAGE(F9,G9),"") -> 0.703 | I9: 0.068 | J9: 0 | K9: 0.159 | L9: 0.887 | M9: 0.848
A10: Duxbury | B10: K-12 | C10: 2789.1 | D10: 19290 | E10: 19876 | F10: 0.677 | G10: 0.602 | H10: =IFERROR(AVERAGE(F10,G10),"") -> 0.6395 | I10: 0.078 | J10: 0.006 | K10: 0.112 | L10: 0.883 | M10: 0.863
A11: East Bridgewater | B11: K-12 | C11: 2050.9 | D11: 16276 | E11: 16840 | F11: 0.459 | G11: 0.402 | H11: =IFERROR(AVERAGE(F11,G11),"") -> 0.4305 | I11: 0.278 | J11: 0.026 | K11: 0.183 | L11: 0.48 | M11: 0.355
A12: Halifax | B12: K-6 | C12: 563.2 | D12: 14046 | E12: 17443 | F12: 0.539 | G12: 0.487 | H12: =IFERROR(AVERAGE(F12,G12),"") -> 0.513 | I12: 0.257 | J12: 0.009 | K12: 0.188 | L12: 0.5 | M12: 0
A13: Hanover | B13: K-12 | C13: 2598.1 | D13: 17167 | E13: 18184 | F13: 0.584 | G13: 0.579 | H13: =IFERROR(AVERAGE(F13,G13),"") -> 0.5815 | I13: 0.109 | J13: 0.013 | K13: 0.215 | L13: 0.735 | M13: 0.667
A14: Hingham | B14: K-12 | C14: 3785.5 | D14: 20124 | E14: 21102 | F14: 0.744 | G14: 0.711 | H14: =IFERROR(AVERAGE(F14,G14),"") -> 0.7275 | I14: 0.072 | J14: 0.006 | K14: 0.165 | L14: 0.867 | M14: 0.817
A15: Holbrook | B15: K-12 | C15: 1325.2 | D15: 16711 | E15: 17813 | F15: 0.377 | G15: 0.372 | H15: =IFERROR(AVERAGE(F15,G15),"") -> 0.3745 | I15: 0.44 | J15: 0.071 | K15: 0.209 | L15: 0.569 | M15: 0.411
A16: Hull | B16: K-12 | C16: 767.5 | D16: 28867 | E16: 29614 | F16: 0.469 | G16: 0.445 | H16: =IFERROR(AVERAGE(F16,G16),"") -> 0.457 | I16: 0.332 | J16: 0.012 | K16: 0.222 | L16: 0.694 | M16: 0.609
... A31: MASSACHUSETTS | B31: STATE | C31: 865749.1 | D31: 21261 | E31: 21886 | F31: 0.42 | G31: 0.41 | H31: =IFERROR(AVERAGE(F31,G31),"") -> 0.415 | I31: 0.423 | J31: 0.121 | K31: 0.194 | L31: 0.58 | M31: 0.5

Sheet YoY Change
A1: Year-over-Year Change: FY23 → FY24 (same district, same metrics)
A2: Positive PPE delta = more spending. Positive MCAS delta = improved outcomes. Positive LowInc delta = demographic shift toward higher need.
A4: District | B4: Type | C4: In-Dist PPE FY23 | D4: In-Dist PPE FY24 | E4: % Chg PPE | F4: Avg M+E 2023 | G4: Avg M+E 2024 | H4: Δ Avg M+E (pp) | I4: Low Inc 2023 | J4: Low Inc 2024 | K4: Δ Low Inc (pp)
A5: Abington | B5: K-12 | C5: ='Data 2023'!D5 -> 16610 | D5: ='Data 2024'!D5 -> 17097 | E5: =IFERROR((D5-C5)/C5,"") -> 0.029319687 | F5: ='Data 2023'!H5 -> 0.4545 | G5: ='Data 2024'!H5 -> 0.4165 | H5: =IFERROR(G5-F5,"") -> -0.038 | I5: ='Data 2023'!I5 -> 0.344 | J5: ='Data 2024'!I5 -> 0.325 | K5: =IFERROR(J5-I5,"") -> -0.019
A6: Braintree | B6: K-12 | C6: ='Data 2023'!D6 -> 17739 | D6: ='Data 2024'!D6 -> 19549 | E6: =IFERROR((D6-C6)/C6,"") -> 0.10203506 | F6: ='Data 2023'!H6 -> 0.5385 | G6: ='Data 2024'!H6 -> 0.521 | H6: =IFERROR(G6-F6,"") -> -0.0175 | I6: ='Data 2023'!I6 -> 0.27 | J6: ='Data 2024'!I6 -> 0.276 | K6: =IFERROR(J6-I6,"") -> 0.006
A7: Bridgewater-Raynham | B7: K-12 Reg | C7: ='Data 2023'!D7 -> 15642 | D7: ='Data 2024'!D7 -> 16125 | E7: =IFERROR((D7-C7)/C7,"") -> 0.030878404 | F7: ='Data 2023'!H7 -> 0.417 | G7: ='Data 2024'!H7 -> 0.401 | H7: =IFERROR(G7-F7,"") -> -0.016 | I7: ='Data 2023'!I7 -> 0.264 | J7: ='Data 2024'!I7 -> 0.264 | K7: =IFERROR(J7-I7,"") -> 0
A8: Carver | B8: K-12 | C8: ='Data 2023'!D8 -> 18506 | D8: ='Data 2024'!D8 -> 19247 | E8: =IFERROR((D8-C8)/C8,"") -> 0.040041068 | F8: ='Data 2023'!H8 -> 0.3005 | G8: ='Data 2024'!H8 -> 0.309 | H8: =IFERROR(G8-F8,"") -> 0.0085 | I8: ='Data 2023'!I8 -> 0.31 | J8: ='Data 2024'!I8 -> 0.295 | K8: =IFERROR(J8-I8,"") -> -0.015
A9: Cohasset | B9: K-12 | C9: ='Data 2023'!D9 -> 21828 | D9: ='Data 2024'!D9 -> 22516 | E9: =IFERROR((D9-C9)/C9,"") -> 0.03151915 | F9: ='Data 2023'!H9 -> 0.703 | G9: ='Data 2024'!H9 -> 0.678 | H9: =IFERROR(G9-F9,"") -> -0.025 | I9: ='Data 2023'!I9 -> 0.068 | J9: ='Data 2024'!I9 -> 0.063 | K9: =IFERROR(J9-I9,"") -> -0.005
A10: Duxbury | B10: K-12 | C10: ='Data 2023'!D10 -> 19290 | D10: ='Data 2024'!D10 -> 20115 | E10: =IFERROR((D10-C10)/C10,"") -> 0.042768274 | F10: ='Data 2023'!H10 -> 0.6395 | G10: ='Data 2024'!H10 -> 0.61 | H10: =IFERROR(G10-F10,"") -> -0.0295 | I10: ='Data 2023'!I10 -> 0.078 | J10: ='Data 2024'!I10 -> 0.087 | K10: =IFERROR(J10-I10,"") -> 0.009
A11: East Bridgewater | B11: K-12 | C11: ='Data 2023'!D11 -> 16276 | D11: ='Data 2024'!D11 -> 17593 | E11: =IFERROR((D11-C11)/C11,"") -> 0.080916687 | F11: ='Data 2023'!H11 -> 0.4305 | G11: ='Data 2024'!H11 -> 0.3925 | H11: =IFERROR(G11-F11,"") -> -0.038 | I11: ='Data 2023'!I11 -> 0.278 | J11: ='Data 2024'!I11 -> 0.279 | K11: =IFERROR(J11-I11,"") -> 0.001
A12: Halifax | B12: K-6 | C12: ='Data 2023'!D12 -> 14046 | D12: ='Data 2024'!D12 -> 17023 | E12: =IFERROR((D12-C12)/C12,"") -> 0.21194646 | F12: ='Data 2023'!H12 -> 0.513 | G12: ='Data 2024'!H12 -> 0.5495 | H12: =IFERROR(G12-F12,"") -> 0.0365 | I12: ='Data 2023'!I12 -> 0.257 | J12: ='Data 2024'!I12 -> 0.271 | K12: =IFERROR(J12-I12,"") -> 0.014
A13: Hanover | B13: K-12 | C13: ='Data 2023'!D13 -> 17167 | D13: ='Data 2024'!D13 -> 16823 | E13: =IFERROR((D13-C13)/C13,"") -> -0.020038446 | F13: ='Data 2023'!H13 -> 0.5815 | G13: ='Data 2024'!H13 -> 0.5735 | H13: =IFERROR(G13-F13,"") -> -0.008 | I13: ='Data 2023'!I13 -> 0.109 | J13: ='Data 2024'!I13 -> 0.111 | K13: =IFERROR(J13-I13,"") -> 0.002
A14: Hingham | B14: K-12 | C14: ='Data 2023'!D14 -> 20124 | D14: ='Data 2024'!D14 -> 20479 | E14: =IFERROR((D14-C14)/C14,"") -> 0.017640628 | F14: ='Data 2023'!H14 -> 0.7275 | G14: ='Data 2024'!H14 -> 0.7345 | H14: =IFERROR(G14-F14,"") -> 0.007 | I14: ='Data 2023'!I14 -> 0.072 | J14: ='Data 2024'!I14 -> 0.078 | K14: =IFERROR(J14-I14,"") -> 0.006
A15: Holbrook | B15: K-12 | C15: ='Data 2023'!D15 -> 16711 | D15: ='Data 2024'!D15 -> 17567 | E15: =IFERROR((D15-C15)/C15,"") -> 0.051223745 | F15: ='Data 2023'!H15 -> 0.3745 | G15: ='Data 2024'!H15 -> 0.361 | H15: =IFERROR(G15-F15,"") -> -0.0135 | I15: ='Data 2023'!I15 -> 0.44 | J15: ='Data 2024'!I15 -> 0.438 | K15: =IFERROR(J15-I15,"") -> -0.002
A16: Hull | B16: K-12 | C16: ='Data 2023'!D16 -> 28867 | D16: ='Data 2024'!D16 -> 31139 | E16: =IFERROR((D16-C16)/C16,"") -> 0.078705789 | F16: ='Data 2023'!H16 -> 0.457 | G16: ='Data 2024'!H16 -> 0.4995 | H16: =IFERROR(G16-F16,"") -> 0.0425 | I16: ='Data 2023'!I16 -> 0.332 | J16: ='Data 2024'!I16 -> 0.334 | K16: =IFERROR(J16-I16,"") -> 0.002
... A31: MASSACHUSETTS | B31: STATE | C31: ='Data 2023'!D31 -> 21261 | D31: ='Data 2024'!D31 -> 22408 | E31: =IFERROR((D31-C31)/C31,"") -> 0.053948544 | F31: ='Data 2023'!H31 -> 0.415 | G31: ='Data 2024'!H31 -> 0.4 | H31: =IFERROR(G31-F31,"") -> -0.015 | I31: ='Data 2023'!I31 -> 0.423 | J31: ='Data 2024'!I31 -> 0.422 | K31: =IFERROR(J31-I31,"") -> -0.001

Sheet Analysis
A1: Correlation Analysis — controlling for demographics
A2: K-12 districts only (excludes Halifax/Kingston K-6, Silver Lake 7-12, voc-techs, state). Hull kept in for completeness but flagged as PPE outlier.
A4: K-12 helper block (FY24)
A5: District | B5: In-Dist PPE | C5: Avg M+E | D5: Low Inc %
A6: ='Data 2024'!A5 -> Abington | B6: ='Data 2024'!D5 -> 17097 | C6: ='Data 2024'!H5 -> 0.4165 | D6: ='Data 2024'!I5 -> 0.325
A7: ='Data 2024'!A6 -> Braintree | B7: ='Data 2024'!D6 -> 19549 | C7: ='Data 2024'!H6 -> 0.521 | D7: ='Data 2024'!I6 -> 0.276
A8: ='Data 2024'!A7 -> Bridgewater-Raynham | B8: ='Data 2024'!D7 -> 16125 | C8: ='Data 2024'!H7 -> 0.401 | D8: ='Data 2024'!I7 -> 0.264
A9: ='Data 2024'!A8 -> Carver | B9: ='Data 2024'!D8 -> 19247 | C9: ='Data 2024'!H8 -> 0.309 | D9: ='Data 2024'!I8 -> 0.295
A10: ='Data 2024'!A9 -> Cohasset | B10: ='Data 2024'!D9 -> 22516 | C10: ='Data 2024'!H9 -> 0.678 | D10: ='Data 2024'!I9 -> 0.063
A11: ='Data 2024'!A10 -> Duxbury | B11: ='Data 2024'!D10 -> 20115 | C11: ='Data 2024'!H10 -> 0.61 | D11: ='Data 2024'!I10 -> 0.087
A12: ='Data 2024'!A11 -> East Bridgewater | B12: ='Data 2024'!D11 -> 17593 | C12: ='Data 2024'!H11 -> 0.3925 | D12: ='Data 2024'!I11 -> 0.279
A13: ='Data 2024'!A13 -> Hanover | B13: ='Data 2024'!D13 -> 16823 | C13: ='Data 2024'!H13 -> 0.5735 | D13: ='Data 2024'!I13 -> 0.111
A14: ='Data 2024'!A14 -> Hingham | B14: ='Data 2024'!D14 -> 20479 | C14: ='Data 2024'!H14 -> 0.7345 | D14: ='Data 2024'!I14 -> 0.078
A15: ='Data 2024'!A15 -> Holbrook | B15: ='Data 2024'!D15 -> 17567 | C15: ='Data 2024'!H15 -> 0.361 | D15: ='Data 2024'!I15 -> 0.438
A16: ='Data 2024'!A16 -> Hull | B16: ='Data 2024'!D16 -> 31139 | C16: ='Data 2024'!H16 -> 0.4995 | D16: ='Data 2024'!I16 -> 0.334
A17: ='Data 2024'!A18 -> Marshfield | B17: ='Data 2024'!D18 -> 19487 | C17: ='Data 2024'!H18 -> 0.553 | D17: ='Data 2024'!I18 -> 0.188
A18: ='Data 2024'!A19 -> Middleborough | B18: ='Data 2024'!D19 -> 19536 | C18: ='Data 2024'!H19 -> 0.3665 | D18: ='Data 2024'!I19 -> 0.407
A19: ='Data 2024'!A20 -> Norwell | B19: ='Data 2024'!D20 -> 19525 | C19: ='Data 2024'!H20 -> 0.6695 | D19: ='Data 2024'!I20 -> 0.058
A20: ='Data 2024'!A21 -> Pembroke | B20: ='Data 2024'!D21 -> 18911 | C20: ='Data 2024'!H21 -> 0.5085 | D20: ='Data 2024'!I21 -> 0.18
A21: ='Data 2024'!A22 -> Plymouth | B21: ='Data 2024'!D22 -> 22128 | C21: ='Data 2024'!H22 -> 0.417 | D21: ='Data 2024'!I22 -> 0.315
A22: ='Data 2024'!A23 -> Quincy | B22: ='Data 2024'!D23 -> 20257 | C22: ='Data 2024'!H23 -> 0.4275 | D22: ='Data 2024'!I23 -> 0.472
A23: ='Data 2024'!A24 -> Rockland | B23: ='Data 2024'!D24 -> 21153 | C23: ='Data 2024'!H24 -> 0.381 | D23: ='Data 2024'!I24 -> 0.472
A24: ='Data 2024'!A25 -> Scituate | B24: ='Data 2024'!D25 -> 20435 | C24: ='Data 2024'!H25 -> 0.5975 | D24: ='Data 2024'!I25 -> 0.118
A25: ='Data 2024'!A27 -> Weymouth | B25: ='Data 2024'!D27 -> 19597 | C25: ='Data 2024'!H27 -> 0.392 | D25: ='Data 2024'!I27 -> 0.405
A26: ='Data 2024'!A28 -> Whitman-Hanson | B26: ='Data 2024'!D28 -> 18079 | C26: ='Data 2024'!H28 -> 0.38 | D26: ='Data 2024'!I28 -> 0.305
A28: Correlations (FY24, K-12 districts)
A29: PPE ↔ Avg M+E (raw) | B29: =CORREL(B6:B26,C6:C26) -> 0.21201233
A30: PPE ↔ Low Income % (raw) | B30: =CORREL(B6:B26,D6:D26) -> 0.040428618
A31: Low Income % ↔ Avg M+E (raw) | B31: =CORREL(D6:D26,C6:C26) -> -0.85346261
A33: Partial correlation: PPE ↔ Avg M+E | controlling Low Inc % | B33: =(B29-B30*B31)/SQRT((1-B30^2)*(1-B31^2)) -> 0.47340771
A35: K-12 averages (FY24)
A36: Avg In-Dist PPE | B36: =AVERAGE(B6:B26) -> 19874.19
A37: Avg ELA+Math M+E | B37: =AVERAGE(C6:C26) -> 0.48519048
A38: Avg Low Income % | B38: =AVERAGE(D6:D26) -> 0.26047619
A40: Residuals: actual Avg M+E vs demographic prediction (FY24)
A41: Uses simple linear regression of Avg M+E on Low Income %. Positive = outperforming demographics, negative = underperforming.
A42: District | B42: Actual Avg M+E | C42: Expected from LowInc | D42: Residual (pp)
A43: ='Data 2024'!A5 -> Abington | B43: ='Data 2024'!H5 -> 0.4165 | C43: =SLOPE(C6:C26,D6:D26)*D6+INTERCEPT(C6:C26,D6:D26) -> 0.4364675 | D43: =B43-C43 -> -0.019967503
A44: ='Data 2024'!A6 -> Braintree | B44: ='Data 2024'!H6 -> 0.521 | C44: =SLOPE(C6:C26,D6:D26)*D7+INTERCEPT(C6:C26,D6:D26) -> 0.4734682 | D44: =B44-C44 -> 0.047531804
A45: ='Data 2024'!A7 -> Bridgewater-Raynham | B45: ='Data 2024'!H7 -> 0.401 | C45: =SLOPE(C6:C26,D6:D26)*D8+INTERCEPT(C6:C26,D6:D26) -> 0.48252959 | D45: =B45-C45 -> -0.081529591
...

Sheet Multi-Year Residuals
A1: Multi-year stability of "best scores for the money" residuals
A2: Same four-variable regression (Low Inc %, SWD %, EL %, In-Dist PPE) run separately for each year.
A3: 2020 omitted (no MCAS administered due to COVID). Residuals in percentage points.
A5: RESIDUALS BY YEAR (percentage points) | N5: INPUTS BY YEAR (helper block)
A6: District | B6: FY2019 | C6: FY2021 | D6: FY2022 | E6: FY2023 | F6: FY2024 | G6: Mean | H6: StDev | I6: Min | J6: Max | K6: Sign | N6: FY2019
A7: Abington | B7: =IFERROR((O8-(O31+O32*P8+O33*Q8+O34*R8+O35*S8))*100,"") -> -3.1246313 | C7: =IFERROR((O41-(O64+O65*P41+O66*Q41+O67*R41+O68*S41))*100,"") -> 0.32220678 | D7: =IFERROR((O74-(O97+O98*P74+O99*Q74+O100*R74+O101*S74))*100,"") -> 0.83228801 | E7: =IFERROR((O107-(O130+O131*P107+O132*Q107+O133*R107+O134*S107))*100,"") -> -3.586641 | F7: =IFERROR((O140-(O163+O164*P140+O165*Q140+O166*R140+O167*S140))*100,"") -> -4.9689589 | G7: =AVERAGE(B7:F7) -> -2.1051473 | H7: =STDEV(B7:F7) -> 2.5473595 | I7: =MIN(B7:F7) -> -4.9689589 | J7: =MAX(B7:F7) -> 0.83228801 | K7: =IF(MIN(B7:F7)>0,"all +",IF(MAX(B7:F7)<0,"all -","mixed")) -> mixed | N7: District | O7: Avg M+E | P7: Low Inc % | Q7: SWD % | R7: EL % | S7: In-Dist PPE
A8: Braintree | B8: =IFERROR((O9-(O31+O32*P9+O33*Q9+O34*R9+O35*S9))*100,"") -> 1.6452993 | C8: =IFERROR((O42-(O64+O65*P42+O66*Q42+O67*R42+O68*S42))*100,"") -> 1.7345251 | D8: =IFERROR((O75-(O97+O98*P75+O99*Q75+O100*R75+O101*S75))*100,"") -> 2.8621091 | E8: =IFERROR((O108-(O130+O131*P108+O132*Q108+O133*R108+O134*S108))*100,"") -> 0.81603526 | F8: =IFERROR((O141-(O163+O164*P141+O165*Q141+O166*R141+O167*S141))*100,"") -> 0.91178397 | G8: =AVERAGE(B8:F8) -> 1.5939505 | H8: =STDEV(B8:F8) -> 0.82175533 | I8: =MIN(B8:F8) -> 0.81603526 | J8: =MAX(B8:F8) -> 2.8621091 | K8: =IF(MIN(B8:F8)>0,"all +",IF(MAX(B8:F8)<0,"all -","mixed")) -> all + | N8: Abington | O8: 0.527 | P8: 0.218 | Q8: 0.159 | R8: 0.05 | S8: 14014
A9: Bridgewater-Raynham | B9: =IFERROR((O10-(O31+O32*P10+O33*Q10+O34*R10+O35*S10))*100,"") -> 1.6306016 | C9: =IFERROR((O43-(O64+O65*P43+O66*Q43+O67*R43+O68*S43))*100,"") -> -1.9036873 | D9: =IFERROR((O76-(O97+O98*P76+O99*Q76+O100*R76+O101*S76))*100,"") -> -0.73733906 | E9: =IFERROR((O109-(O130+O131*P109+O132*Q109+O133*R109+O134*S109))*100,"") -> -2.3190286 | F9: =IFERROR((O142-(O163+O164*P142+O165*Q142+O166*R142+O167*S142))*100,"") -> -1.2150907 | G9: =AVERAGE(B9:F9) -> -0.90890882 | H9: =STDEV(B9:F9) -> 1.5451795 | I9: =MIN(B9:F9) -> -2.3190286 | J9: =MAX(B9:F9) -> 1.6306016 | K9: =IF(MIN(B9:F9)>0,"all +",IF(MAX(B9:F9)<0,"all -","mixed")) -> mixed | N9: Braintree | O9: 0.6235 | P9: 0.179 | Q9: 0.202 | R9: 0.058 | S9: 14507
A10: Carver | B10: =IFERROR((O11-(O31+O32*P11+O33*Q11+O34*R11+O35*S11))*100,"") -> -8.8226496 | C10: =IFERROR((O44-(O64+O65*P44+O66*Q44+O67*R44+O68*S44))*100,"") -> -11.363427 | D10: =IFERROR((O77-(O97+O98*P77+O99*Q77+O100*R77+O101*S77))*100,"") -> -9.1717002 | E10: =IFERROR((O110-(O130+O131*P110+O132*Q110+O133*R110+O134*S110))*100,"") -> -10.908209 | F10: =IFERROR((O143-(O163+O164*P143+O165*Q143+O166*R143+O167*S143))*100,"") -> -8.9137299 | G10: =AVERAGE(B10:F10) -> -9.8359432 | H10: =STDEV(B10:F10) -> 1.204307 | I10: =MIN(B10:F10) -> -11.363427 | J10: =MAX(B10:F10) -> -8.8226496 | K10: =IF(MIN(B10:F10)>0,"all +",IF(MAX(B10:F10)<0,"all -","mixed")) -> all - | N10: Bridgewater-Raynham | O10: 0.584 | P10: 0.161 | Q10: 0.162 | R10: 0.015 | S10: 13022
A11: Cohasset | B11: =IFERROR((O12-(O31+O32*P12+O33*Q12+O34*R12+O35*S12))*100,"") -> -5.8548119 | C11: =IFERROR((O45-(O64+O65*P45+O66*Q45+O67*R45+O68*S45))*100,"") -> -6.6285647 | D11: =IFERROR((O78-(O97+O98*P78+O99*Q78+O100*R78+O101*S78))*100,"") -> -1.0844443 | E11: =IFERROR((O111-(O130+O131*P111+O132*Q111+O133*R111+O134*S111))*100,"") -> 1.7715128 | F11: =IFERROR((O144-(O163+O164*P144+O165*Q144+O166*R144+O167*S144))*100,"") -> -0.10461925 | G11: =AVERAGE(B11:F11) -> -2.3801855 | H11: =STDEV(B11:F11) -> 3.6815588 | I11: =MIN(B11:F11) -> -6.6285647 | J11: =MAX(B11:F11) -> 1.7715128 | K11: =IF(MIN(B11:F11)>0,"all +",IF(MAX(B11:F11)<0,"all -","mixed")) -> mixed | N11: Carver | O11: 0.4305 | P11: 0.219 | Q11: 0.191 | R11: 0.013 | S11: 15071
A12: Duxbury | B12: =IFERROR((O13-(O31+O32*P13+O33*Q13+O34*R13+O35*S13))*100,"") -> -3.4959261 | C12: =IFERROR((O46-(O64+O65*P46+O66*Q46+O67*R46+O68*S46))*100,"") -> -2.3842374 | D12: =IFERROR((O79-(O97+O98*P79+O99*Q79+O100*R79+O101*S79))*100,"") -> -3.9159908 | E12: =IFERROR((O112-(O130+O131*P112+O132*Q112+O133*R112+O134*S112))*100,"") -> -1.924859 | F12: =IFERROR((O145-(O163+O164*P145+O165*Q145+O166*R145+O167*S145))*100,"") -> -1.2013225 | G12: =AVERAGE(B12:F12) -> -2.5844672 | H12: =STDEV(B12:F12) -> 1.1171366 | I12: =MIN(B12:F12) -> -3.9159908 | J12: =MAX(B12:F12) -> -1.2013225 | K12: =IF(MIN(B12:F12)>0,"all +",IF(MAX(B12:F12)<0,"all -","mixed")) -> all - | N12: Cohasset | O12: 0.6715 | P12: 0.052 | Q12: 0.135 | R12: 0.002 | S12: 16871
A13: East Bridgewater | B13: =IFERROR((O14-(O31+O32*P14+O33*Q14+O34*R14+O35*S14))*100,"") -> -0.83329414 | C13: =IFERROR((O47-(O64+O65*P47+O66*Q47+O67*R47+O68*S47))*100,"") -> -2.0134921 | D13: =IFERROR((O80-(O97+O98*P80+O99*Q80+O100*R80+O101*S80))*100,"") -> -3.0600727 | E13: =IFERROR((O113-(O130+O131*P113+O132*Q113+O133*R113+O134*S113))*100,"") -> 0.20560875 | F13: =IFERROR((O146-(O163+O164*P146+O165*Q146+O166*R146+O167*S146))*100,"") -> -1.6783603 | G13: =AVERAGE(B13:F13) -> -1.4759221 | H13: =STDEV(B13:F13) -> 1.2328841 | I13: =MIN(B13:F13) -> -3.0600727 | J13: =MAX(B13:F13) -> 0.20560875 | K13: =IF(MIN(B13:F13)>0,"all +",IF(MAX(B13:F13)<0,"all -","mixed")) -> mixed | N13: Duxbury | O13: 0.68 | P13: 0.052 | Q13: 0.153 | R13: 0.003 | S13: 15935
A14: Hanover | B14: =IFERROR((O15-(O31+O32*P15+O33*Q15+O34*R15+O35*S15))*100,"") -> -3.4004046 | C14: =IFERROR((O48-(O64+O65*P48+O66*Q48+O67*R48+O68*S48))*100,"") -> -0.61985612 | D14: =IFERROR((O81-(O97+O98*P81+O99*Q81+O100*R81+O101*S81))*100,"") -> -3.9294584 | E14: =IFERROR((O114-(O130+O131*P114+O132*Q114+O133*R114+O134*S114))*100,"") -> -2.5096992 | F14: =IFERROR((O147-(O163+O164*P147+O165*Q147+O166*R147+O167*S147))*100,"") -> -1.2424664 | G14: =AVERAGE(B14:F14) -> -2.340377 | H14: =STDEV(B14:F14) -> 1.4002775 | I14: =MIN(B14:F14) -> -3.9294584 | J14: =MAX(B14:F14) -> -0.61985612 | K14: =IF(MIN(B14:F14)>0,"all +",IF(MAX(B14:F14)<0,"all -","mixed")) -> all - | N14: East Bridgewater | O14: 0.5135 | P14: 0.181 | Q14: 0.191 | R14: 0.008 | S14: 12396
A15: Hingham | B15: =IFERROR((O16-(O31+O32*P16+O33*Q16+O34*R16+O35*S16))*100,"") -> 8.3203573 | C15: =IFERROR((O49-(O64+O65*P49+O66*Q49+O67*R49+O68*S49))*100,"") -> 8.5514146 | D15: =IFERROR((O82-(O97+O98*P82+O99*Q82+O100*R82+O101*S82))*100,"") -> 8.004054 | E15: =IFERROR((O115-(O130+O131*P115+O132*Q115+O133*R115+O134*S115))*100,"") -> 5.584046 | F15: =IFERROR((O148-(O163+O164*P148+O165*Q148+O166*R148+O167*S148))*100,"") -> 9.0044605 | G15: =AVERAGE(B15:F15) -> 7.8928665 | H15: =STDEV(B15:F15) -> 1.3411832 | I15: =MIN(B15:F15) -> 5.584046 | J15: =MAX(B15:F15) -> 9.0044605 | K15: =IF(MIN(B15:F15)>0,"all +",IF(MAX(B15:F15)<0,"all -","mixed")) -> all + | N15: Hanover | O15: 0.624 | P15: 0.084 | Q15: 0.178 | R15: 0.01 | S15: 14106
A16: Holbrook | B16: =IFERROR((O17-(O31+O32*P17+O33*Q17+O34*R17+O35*S17))*100,"") -> -1.4180424 | C16: =IFERROR((O50-(O64+O65*P50+O66*Q50+O67*R50+O68*S50))*100,"") -> -1.3362074 | D16: =IFERROR((O83-(O97+O98*P83+O99*Q83+O100*R83+O101*S83))*100,"") -> 2.1366397 | E16: =IFERROR((O116-(O130+O131*P116+O132*Q116+O133*R116+O134*S116))*100,"") -> 5.4646626 | F16: =IFERROR((O149-(O163+O164*P149+O165*Q149+O166*R149+O167*S149))*100,"") -> 4.7325263 | G16: =AVERAGE(B16:F16) -> 1.9159157 | H16: =STDEV(B16:F16) -> 3.2506615 | I16: =MIN(B16:F16) -> -1.4180424 | J16: =MAX(B16:F16) -> 5.4646626 | K16: =IF(MIN(B16:F16)>0,"all +",IF(MAX(B16:F16)<0,"all -","mixed")) -> mixed | N16: Hingham | O16: 0.7855 | P16: 0.047 | Q16: 0.13 | R16: 0.003 | S16: 14029
A17: Hull | B17: =IFERROR((O18-(O31+O32*P18+O33*Q18+O34*R18+O35*S18))*100,"") -> 5.7027426 | C17: =IFERROR((O51-(O64+O65*P51+O66*Q51+O67*R51+O68*S51))*100,"") -> 2.7548525 | D17: =IFERROR((O84-(O97+O98*P84+O99*Q84+O100*R84+O101*S84))*100,"") -> 0.4474174 | E17: =IFERROR((O117-(O130+O131*P117+O132*Q117+O133*R117+O134*S117))*100,"") -> -2.1258386 | F17: =IFERROR((O150-(O163+O164*P150+O165*Q150+O166*R150+O167*S150))*100,"") -> -1.8758708 | G17: =AVERAGE(B17:F17) -> 0.9806606 | H17: =STDEV(B17:F17) -> 3.2992527 | I17: =MIN(B17:F17) -> -2.1258386 | J17: =MAX(B17:F17) -> 5.7027426 | K17: =IF(MIN(B17:F17)>0,"all +",IF(MAX(B17:F17)<0,"all -","mixed")) -> mixed | N17: Holbrook | O17: 0.449 | P17: 0.315 | Q17: 0.214 | R17: 0.074 | S17: 13957
A18: Marshfield | B18: =IFERROR((O19-(O31+O32*P19+O33*Q19+O34*R19+O35*S19))*100,"") -> 10.639827 | C18: =IFERROR((O52-(O64+O65*P52+O66*Q52+O67*R52+O68*S52))*100,"") -> 5.1572644 | D18: =IFERROR((O85-(O97+O98*P85+O99*Q85+O100*R85+O101*S85))*100,"") -> 4.1216692 | E18: =IFERROR((O118-(O130+O131*P118+O132*Q118+O133*R118+O134*S118))*100,"") -> 3.4280043 | F18: =IFERROR((O151-(O163+O164*P151+O165*Q151+O166*R151+O167*S151))*100,"") -> 1.3269804 | G18: =AVERAGE(B18:F18) -> 4.934749 | H18: =STDEV(B18:F18) -> 3.4837049 | I18: =MIN(B18:F18) -> 1.3269804 | J18: =MAX(B18:F18) -> 10.639827 | K18: =IF(MIN(B18:F18)>0,"all +",IF(MAX(B18:F18)<0,"all -","mixed")) -> all + | N18: Hull | O18: 0.5435 | P18: 0.304 | Q18: 0.216 | R18: 0.003 | S18: 21528
A19: Middleborough | B19: =IFERROR((O20-(O31+O32*P20+O33*Q20+O34*R20+O35*S20))*100,"") -> 4.9981169 | C19: =IFERROR((O53-(O64+O65*P53+O66*Q53+O67*R53+O68*S53))*100,"") -> 6.5406055 | D19: =IFERROR((O86-(O97+O98*P86+O99*Q86+O100*R86+O101*S86))*100,"") -> 7.683389 | E19: =IFERROR((O119-(O130+O131*P119+O132*Q119+O133*R119+O134*S119))*100,"") -> 5.1895195 | F19: =IFERROR((O152-(O163+O164*P152+O165*Q152+O166*R152+O167*S152))*100,"") -> 7.4641151 | G19: =AVERAGE(B19:F19) -> 6.3751492 | H19: =STDEV(B19:F19) -> 1.2476628 | I19: =MIN(B19:F19) -> 4.9981169 | J19: =MAX(B19:F19) -> 7.683389 | K19: =IF(MIN(B19:F19)>0,"all +",IF(MAX(B19:F19)<0,"all -","mixed")) -> all + | N19: Marshfield | O19: 0.722 | P19: 0.119 | Q19: 0.17 | R19: 0.011 | S19: 13611
A20: Norwell | B20: =IFERROR((O21-(O31+O32*P21+O33*Q21+O34*R21+O35*S21))*100,"") -> -0.25458907 | C20: =IFERROR((O54-(O64+O65*P54+O66*Q54+O67*R54+O68*S54))*100,"") -> 0.35135231 | D20: =IFERROR((O87-(O97+O98*P87+O99*Q87+O100*R87+O101*S87))*100,"") -> -0.13432353 | E20: =IFERROR((O120-(O130+O131*P120+O132*Q120+O133*R120+O134*S120))*100,"") -> -0.2365019 | F20: =IFERROR((O153-(O163+O164*P153+O165*Q153+O166*R153+O167*S153))*100,"") -> 2.6930423 | G20: =AVERAGE(B20:F20) -> 0.48379602 | H20: =STDEV(B20:F20) -> 1.259407 | I20: =MIN(B20:F20) -> -0.25458907 | J20: =MAX(B20:F20) -> 2.6930423 | K20: =IF(MIN(B20:F20)>0,"all +",IF(MAX(B20:F20)<0,"all -","mixed")) -> mixed | N20: Middleborough | O20: 0.4795 | P20: 0.29 | Q20: 0.196 | R20: 0.01 | S20: 14705
A21: Pembroke | B21: =IFERROR((O22-(O31+O32*P22+O33*Q22+O34*R22+O35*S22))*100,"") -> -1.8403082 | C21: =IFERROR((O55-(O64+O65*P55+O66*Q55+O67*R55+O68*S55))*100,"") -> -0.69693308 | D21: =IFERROR((O88-(O97+O98*P88+O99*Q88+O100*R88+O101*S88))*100,"") -> -1.4250478 | E21: =IFERROR((O121-(O130+O131*P121+O132*Q121+O133*R121+O134*S121))*100,"") -> -0.26860975 | F21: =IFERROR((O154-(O163+O164*P154+O165*Q154+O166*R154+O167*S154))*100,"") -> -1.6315517 | G21: =AVERAGE(B21:F21) -> -1.1724901 | H21: =STDEV(B21:F21) -> 0.66401395 | I21: =MIN(B21:F21) -> -1.8403082 | J21: =MAX(B21:F21) -> -0.26860975 | K21: =IF(MIN(B21:F21)>0,"all +",IF(MAX(B21:F21)<0,"all -","mixed")) -> all - | N21: Norwell | O21: 0.725 | P21: 0.038 | Q21: 0.157 | R21: 0.003 | S21: 15764
A22: Plymouth | B22: =IFERROR((O23-(O31+O32*P23+O33*Q23+O34*R23+O35*S23))*100,"") -> -4.0423602 | C22: =IFERROR((O56-(O64+O65*P56+O66*Q56+O67*R56+O68*S56))*100,"") -> -1.9148373 | D22: =IFERROR((O89-(O97+O98*P89+O99*Q89+O100*R89+O101*S89))*100,"") -> -1.5004205 | E22: =IFERROR((O122-(O130+O131*P122+O132*Q122+O133*R122+O134*S122))*100,"") -> -1.0927351 | F22: =IFERROR((O155-(O163+O164*P155+O165*Q155+O166*R155+O167*S155))*100,"") -> -5.655804 | G22: =AVERAGE(B22:F22) -> -2.8412314 | H22: =STDEV(B22:F22) -> 1.9415038 | I22: =MIN(B22:F22) -> -5.655804 | J22: =MAX(B22:F22) -> -1.0927351 | K22: =IF(MIN(B22:F22)>0,"all +",IF(MAX(B22:F22)<0,"all -","mixed")) -> all - | N22: Pembroke | O22: 0.605 | P22: 0.124 | Q22: 0.142 | R22: 0.01 | S22: 14217
A23: Quincy | B23: =IFERROR((O24-(O31+O32*P24+O33*Q24+O34*R24+O35*S24))*100,"") -> 1.8842888 | C23: =IFERROR((O57-(O64+O65*P57+O66*Q57+O67*R57+O68*S57))*100,"") -> -1.0012342 | D23: =IFERROR((O90-(O97+O98*P90+O99*Q90+O100*R90+O101*S90))*100,"") -> -1.6315605 | E23: =IFERROR((O123-(O130+O131*P123+O132*Q123+O133*R123+O134*S123))*100,"") -> -0.92839197 | F23: =IFERROR((O156-(O163+O164*P156+O165*Q156+O166*R156+O167*S156))*100,"") -> 0.75469867 | G23: =AVERAGE(B23:F23) -> -0.18443983 | H23: =STDEV(B23:F23) -> 1.4557125 | I23: =MIN(B23:F23) -> -1.6315605 | J23: =MAX(B23:F23) -> 1.8842888 | K23: =IF(MIN(B23:F23)>0,"all +",IF(MAX(B23:F23)<0,"all -","mixed")) -> mixed | N23: Plymouth | O23: 0.5005 | P23: 0.232 | Q23: 0.198 | R23: 0.016 | S23: 17850
A24: Rockland | B24: =IFERROR((O25-(O31+O32*P25+O33*Q25+O34*R25+O35*S25))*100,"") -> -0.20113286 | C24: =IFERROR((O58-(O64+O65*P58+O66*Q58+O67*R58+O68*S58))*100,"") -> 3.3435316 | D24: =IFERROR((O91-(O97+O98*P91+O99*Q91+O100*R91+O101*S91))*100,"") -> 0.94445704 | E24: =IFERROR((O124-(O130+O131*P124+O132*Q124+O133*R124+O134*S124))*100,"") -> 2.6203899 | F24: =IFERROR((O157-(O163+O164*P157+O165*Q157+O166*R157+O167*S157))*100,"") -> 3.1819263 | G24: =AVERAGE(B24:F24) -> 1.9778344 | H24: =STDEV(B24:F24) -> 1.5446368 | I24: =MIN(B24:F24) -> -0.20113286 | J24: =MAX(B24:F24) -> 3.3435316 | K24: =IF(MIN(B24:F24)>0,"all +",IF(MAX(B24:F24)<0,"all -","mixed")) -> mixed | N24: Quincy | O24: 0.5695 | P24: 0.345 | Q24: 0.185 | R24: 0.155 | S24: 15403
A25: Scituate | B25: =IFERROR((O26-(O31+O32*P26+O33*Q26+O34*R26+O35*S26))*100,"") -> 3.7593079 | C25: =IFERROR((O59-(O64+O65*P59+O66*Q59+O67*R59+O68*S59))*100,"") -> 5.2559367 | D25: =IFERROR((O92-(O97+O98*P92+O99*Q92+O100*R92+O101*S92))*100,"") -> 2.6817121 | E25: =IFERROR((O125-(O130+O131*P125+O132*Q125+O133*R125+O134*S125))*100,"") -> 1.677642 | F25: =IFERROR((O158-(O163+O164*P158+O165*Q158+O166*R158+O167*S158))*100,"") -> 0.33850257 | G25: =AVERAGE(B25:F25) -> 2.7426203 | H25: =STDEV(B25:F25) -> 1.8886559 | I25: =MIN(B25:F25) -> 0.33850257 | J25: =MAX(B25:F25) -> 5.2559367 | K25: =IF(MIN(B25:F25)>0,"all +",IF(MAX(B25:F25)<0,"all -","mixed")) -> all + | N25: Rockland | O25: 0.471 | P25: 0.325 | Q25: 0.168 | R25: 0.062 | S25: 15847
A26: Weymouth | B26: =IFERROR((O27-(O31+O32*P27+O33*Q27+O34*R27+O35*S27))*100,"") -> -1.7324258 | C26: =IFERROR((O60-(O64+O65*P60+O66*Q60+O67*R60+O68*S60))*100,"") -> -0.4086775 | D26: =IFERROR((O93-(O97+O98*P93+O99*Q93+O100*R93+O101*S93))*100,"") -> -0.40049125 | E26: =IFERROR((O126-(O130+O131*P126+O132*Q126+O133*R126+O134*S126))*100,"") -> 0.99826777 | F26: =IFERROR((O159-(O163+O164*P159+O165*Q159+O166*R159+O167*S159))*100,"") -> 2.0156576 | G26: =AVERAGE(B26:F26) -> 0.094466167 | H26: =STDEV(B26:F26) -> 1.4442562 | I26: =MIN(B26:F26) -> -1.7324258 | J26: =MAX(B26:F26) -> 2.0156576 | K26: =IF(MIN(B26:F26)>0,"all +",IF(MAX(B26:F26)<0,"all -","mixed")) -> mixed | N26: Scituate | O26: 0.6905 | P26: 0.104 | Q26: 0.142 | R26: 0.006 | S26: 15150
A27: Whitman-Hanson | B27: =IFERROR((O28-(O31+O32*P28+O33*Q28+O34*R28+O35*S28))*100,"") -> -3.5599652 | C27: =IFERROR((O61-(O64+O65*P61+O66*Q61+O67*R61+O68*S61))*100,"") -> -3.7405352 | D27: =IFERROR((O94-(O97+O98*P94+O99*Q94+O100*R94+O101*S94))*100,"") -> -2.7228865 | E27: =IFERROR((O127-(O130+O131*P127+O132*Q127+O133*R127+O134*S127))*100,"") -> -1.8551746 | F27: =IFERROR((O160-(O163+O164*P160+O165*Q160+O166*R160+O167*S160))*100,"") -> -3.9359193 | G27: =AVERAGE(B27:F27) -> -3.1628962 | H27: =STDEV(B27:F27) -> 0.86496237 | I27: =MIN(B27:F27) -> -3.9359193 | J27: =MAX(B27:F27) -> -1.8551746 | K27: =IF(MIN(B27:F27)>0,"all +",IF(MAX(B27:F27)<0,"all -","mixed")) -> all - | N27: Weymouth | O27: 0.457 | P27: 0.286 | Q27: 0.192 | R27: 0.038 | S27: 15198
N28: Whitman-Hanson | O28: 0.49 | P28: 0.202 | Q28: 0.151 | R28: 0.012 | S28: 13403
A30: PERSISTENCE SUMMARY | N30: Coefficients
A31: Districts consistently outperforming (5/5 years positive) | B31: =COUNTIF(K7:K27,"all +") -> 5 | N31: Intercept | O31: =INDEX(LINEST(O8:O28,P8:S28,TRUE(),FALSE()),1,5) -> 0.60722722
A32: Districts consistently underperforming (5/5 years negative) | B32: =COUNTIF(K7:K27,"all -") -> 6 | N32: LowInc coef | O32: =INDEX(LINEST(O8:O28,P8:S28,TRUE(),FALSE()),1,4) -> -1.1240266
A33: Districts mixed (changed sign at least once) | B33: =COUNTIF(K7:K27,"mixed") -> 10 | N33: SWD coef | O33: =INDEX(LINEST(O8:O28,P8:S28,TRUE(),FALSE()),1,3) -> -0.2489418
N34: EL coef | O34: =INDEX(LINEST(O8:O28,P8:S28,TRUE(),FALSE()),1,2) -> 1.1822699
A35: HOW TO READ THIS: | N35: PPE coef | O35: =INDEX(LINEST(O8:O28,P8:S28,TRUE(),FALSE()),1,1) -> 1.2596342e-05
A36: • Mean residual = average across 5 years. The most robust ranking — single-year noise washes out. | N36: R² | O36: =INDEX(LINEST(O8:O28,P8:S28,TRUE(),TRUE()),3,1) -> 0.79512734
A37: • StDev = year-to-year variability of the residual. Low = stable signal. High = noisy.
A38: • Sign column = "all +" or "all -" means the district was on the same side every single year.
A39: This is a strong persistence test — chance alone would put fewer than 1 in 16 districts on | N39: FY2021
A40: the same side for 5 consecutive years. With 11 of 21 districts persistent, this is signal. | N40: District | O40: Avg M+E | P40: Low Inc % | Q40: SWD % | R40: EL % | S40: In-Dist PPE
N41: Abington | O41: 0.4305 | P41: 0.297 | Q41: 0.158 | R41: 0.077 | S41: 14888
A42: WHITMAN-HANSON: Mean -3.2pp, StDev 0.84 (the LOWEST volatility in the negative-residual group). | N42: Braintree | O42: 0.5165 | P42: 0.219 | Q42: 0.199 | R42: 0.061 | S42: 16436
...

Sheet State Comparison
A1: Regional model vs. Statewide model — residuals compared
A2: Same regression specification (Low Inc %, SWD %, EL %, In-Dist PPE) but calibrated on two different peer groups.
A3: Regional model: 21 South Shore K-12 districts (R² avg 0.86). Statewide model: 394 MA K-12 districts (R² avg 0.46).
A5: STATEWIDE-MODEL RESIDUALS, YEAR BY YEAR (percentage points)
A6: District | B6: FY2019 | C6: FY2021 | D6: FY2022 | E6: FY2023 | F6: FY2024 | G6: State Mean | H6: SS Mean | I6: Shift (State - SS) | J6: Story
A7: Hingham | B7: 10.846996 | C7: 12.048998 | D7: 13.30287 | E7: 15.29808 | F7: 18.896039 | G7: 14.078597 | H7: 7.9 | I7: 6.1785966 | J7: Good in both
A8: Hull | B8: 18.921852 | C8: 12.926405 | D8: 7.6501328 | E8: 10.524674 | F8: 15.192451 | G8: 13.043103 | H8: 1 | I8: 12.043103 | J8: Good in both
A9: Braintree | B9: 9.6561472 | C9: 8.6606865 | D9: 9.9386116 | E9: 9.0589224 | F9: 9.2523776 | G9: 9.3133491 | H9: 1.6 | I9: 7.7133491 | J9: Good in both
A10: Marshfield | B10: 13.157071 | C10: 9.8647591 | D10: 6.9989469 | E10: 8.2404646 | F10: 7.4634125 | G10: 9.1449309 | H10: 4.9 | I10: 4.2449309 | J10: Good in both
A11: Quincy | B11: 9.8657423 | C11: 6.6918261 | D11: 10.01317 | E11: 9.0232187 | F11: 8.4368225 | G11: 8.8061559 | H11: -0.2 | I11: 9.0061559 | J11: Looks bad regionally, fine statewide
A12: Scituate | B12: 7.1652839 | C12: 7.7701184 | D12: 6.598619 | E12: 8.2483068 | F12: 7.8162618 | G12: 7.519718 | H12: 2.7 | I12: 4.819718 | J12: Good in both
A13: Norwell | B13: 8.6063916 | C13: 5.9439015 | D13: 5.4260551 | E13: 7.1601961 | F13: 10.025716 | G13: 7.4324521 | H13: 0.5 | I13: 6.9324521 | J13: Good in both
A14: Cohasset | B14: 2.5127299 | C14: 0.29188145 | D14: 4.2888623 | E14: 12.930817 | F14: 12.367827 | G14: 6.4784234 | H14: -2.4 | I14: 8.8784234 | J14: Looks bad regionally, fine statewide
A15: Rockland | B15: 0.88015809 | C15: 4.9122684 | D15: 5.1593149 | E15: 5.1849075 | F15: 5.252982 | G15: 4.2779262 | H15: 2 | I15: 2.2779262 | J15: Good in both
A16: Plymouth | B16: 4.5709433 | C16: 3.5907549 | D16: 3.4861206 | E16: 5.9395578 | F16: 2.2549451 | G16: 3.9684643 | H16: -2.8 | I16: 6.7684643 | J16: Looks bad regionally, fine statewide
A17: Hanover | B17: 2.399476 | C17: 4.1426338 | D17: 1.8911048 | E17: 5.1725645 | F17: 5.4916179 | G17: 3.8194794 | H17: -2.3 | I17: 6.1194794 | J17: Looks bad regionally, fine statewide
A18: Duxbury | B18: 4.68964 | C18: 3.3852971 | D18: -1.4093672 | E18: 2.9367552 | F18: 6.2236605 | G18: 3.1651971 | H18: -2.6 | I18: 5.7651971 | J18: Looks bad regionally, fine statewide
... A27: Carver | B27: -6.0370671 | C27: -9.0462316 | D27: -10.189233 | E27: -12.454025 | F27: -10.418236 | G27: -9.6289584 | H27: -9.8 | I27: 0.17104158 | J27: Bad in both
A30: STATEWIDE PERCENTILE RANKINGS (5-year mean residual)
A31: District | B31: State Rank | C31: Percentile | D31: Interpretation
A32: Hingham | B32: #37 of 394 | C32: 91 | D32: Top 15% statewide
A33: Hull | B33: #50 of 394 | C33: 87 | D33: Top 15% statewide
A34: Braintree | B34: #95 of 394 | C34: 76 | D34: Top 30%
A35: Marshfield | B35: #98 of 394 | C35: 75 | D35: Top 30%
A36: Quincy | B36: #107 of 394 | C36: 73 | D36: Top 30%
A37: Scituate | B37: #130 of 394 | C37: 67 | D37: Above state average
A38: Norwell | B38: #132 of 394 | C38: 67 | D38: Above state average
A39: Cohasset | B39: #152 of 394 | C39: 61 | D39: Above state average
A40: Rockland | B40: #190 of 394 | C40: 52 | D40: Near state average
A41: Plymouth | B41: #196 of 394 | C41: 50 | D41: Near state average
A42: Hanover | B42: #199 of 394 | C42: 49 | D42: Near state average
A43: Duxbury | B43: #200 of 394 | C43: 49 | D43: Near state average
... A52: Carver | B52: #345 of 394 | C52: 13 | D52: Bottom 15% statewide
A55: KEY FINDINGS
A57: 1. CARVER IS THE ONLY DISTRICT WHOSE STORY IS IDENTICAL IN BOTH FRAMES.
A58: Regional residual: -9.8pp. State residual: -9.6pp. Bottom 13% statewide.
A59: The underperformance is not a regional artifact. It holds against any peer group.
A61: 2. MIDDLEBOROUGH WEAKENS SIGNIFICANTLY AGAINST THE STATE BENCHMARK.
A62: Regional residual: +6.4pp (#2 in region). State residual: +2.0pp (48th percentile).
A63: Middleborough is a regional star, not a state exemplar.
...

Sheet Sources & Methods
A1: Sources & Methods
A3: PRIMARY SOURCE
A4: DESE Resource Allocation and District Action Reports (RADAR) — District Comparison Statistics
A5: URL: https://www.doe.mass.edu/research/radar/district-comparison.xlsx
A6: Contains 16 years (2009-2024) of PPE, MCAS, and demographics for every MA public school district.
A8: PAIRING CONVENTION
A9: This workbook pairs FY[N] per-pupil expenditures with Spring [N] MCAS. Both occur within
A10: the same school year [N-1]-[N]. Example: FY24 spending = school year 2023-24 = Spring 2024 MCAS.
A11: This is more rigorous than pairing FY24 spending with Spring 2025 MCAS (which is funded by
A12: FY25 spending not yet reported).
A14: COLUMN DEFINITIONS
A15: In-District PPE: operating expenditures divided by in-district FTE. Excludes out-of-district placements.
... A125: broader MA K-12 universe.
